<?xml version="1.0" ?>
<!-- =================================================================================== -->
<!-- |    This document was autogenerated by xacro from /home/seongjin/Desktop/Seongjin/genesis_simulation_on_linux/My_asset/Crusher_description/urdf/Crusher.xacro | -->
<!-- |    EDITING THIS FILE BY HAND IS NOT RECOMMENDED                                 | -->
<!-- =================================================================================== -->
<robot name="Crusher">
  <material name="silver">
    <color rgba="0.700 0.700 0.700 1.000"/>
  </material>
  <transmission name="Revolute 10_tran">
    <type>transmission_interface/SimpleTransmission</type>
    <joint name="Revolute 10">
      <hardwareInterface>hardware_interface/EffortJointInterface</hardwareInterface>
    </joint>
    <actuator name="Revolute 10_actr">
      <hardwareInterface>hardware_interface/EffortJointInterface</hardwareInterface>
      <mechanicalReduction>1</mechanicalReduction>
    </actuator>
  </transmission>
  <transmission name="Revolute 12_tran">
    <type>transmission_interface/SimpleTransmission</type>
    <joint name="Revolute 12">
      <hardwareInterface>hardware_interface/EffortJointInterface</hardwareInterface>
    </joint>
    <actuator name="Revolute 12_actr">
      <hardwareInterface>hardware_interface/EffortJointInterface</hardwareInterface>
      <mechanicalReduction>1</mechanicalReduction>
    </actuator>
  </transmission>
  <transmission name="Revolute 13_tran">
    <type>transmission_interface/SimpleTransmission</type>
    <joint name="Revolute 13">
      <hardwareInterface>hardware_interface/EffortJointInterface</hardwareInterface>
    </joint>
    <actuator name="Revolute 13_actr">
      <hardwareInterface>hardware_interface/EffortJointInterface</hardwareInterface>
      <mechanicalReduction>1</mechanicalReduction>
    </actuator>
  </transmission>
  <transmission name="Slider 21_tran">
    <type>transmission_interface/SimpleTransmission</type>
    <joint name="Slider 21">
      <hardwareInterface>hardware_interface/EffortJointInterface</hardwareInterface>
    </joint>
    <actuator name="Slider 21_actr">
      <hardwareInterface>hardware_interface/EffortJointInterface</hardwareInterface>
      <mechanicalReduction>1</mechanicalReduction>
    </actuator>
  </transmission>
  <gazebo>
    <plugin filename="libgazebo_ros_control.so" name="control"/>
  </gazebo>
  <gazebo reference="base_link">
    <material>Gazebo/Silver</material>
    <mu1>0.2</mu1>
    <mu2>0.2</mu2>
    <selfCollide>true</selfCollide>
    <gravity>true</gravity>
  </gazebo>
  <gazebo reference="braket1_1">
    <material>Gazebo/Silver</material>
    <mu1>0.2</mu1>
    <mu2>0.2</mu2>
    <selfCollide>true</selfCollide>
  </gazebo>
  <gazebo reference="braket2_1">
    <material>Gazebo/Silver</material>
    <mu1>0.2</mu1>
    <mu2>0.2</mu2>
    <selfCollide>true</selfCollide>
  </gazebo>
  <gazebo reference="motor_1">
    <material>Gazebo/Silver</material>
    <mu1>0.2</mu1>
    <mu2>0.2</mu2>
    <selfCollide>true</selfCollide>
  </gazebo>
  <gazebo reference="motor_shaft_1">
    <material>Gazebo/Silver</material>
    <mu1>0.2</mu1>
    <mu2>0.2</mu2>
    <selfCollide>true</selfCollide>
  </gazebo>
  <gazebo reference="Link1_1">
    <material>Gazebo/Silver</material>
    <mu1>0.2</mu1>
    <mu2>0.2</mu2>
    <selfCollide>true</selfCollide>
  </gazebo>
  <gazebo reference="Link2_1">
    <material>Gazebo/Silver</material>
    <mu1>0.2</mu1>
    <mu2>0.2</mu2>
    <selfCollide>true</selfCollide>
  </gazebo>
  <gazebo reference="Link3_1">
    <material>Gazebo/Silver</material>
    <mu1>0.2</mu1>
    <mu2>0.2</mu2>
    <selfCollide>true</selfCollide>
  </gazebo>
  <gazebo reference="slider_jig_1">
    <material>Gazebo/Silver</material>
    <mu1>0.2</mu1>
    <mu2>0.2</mu2>
    <selfCollide>true</selfCollide>
  </gazebo>
  <gazebo reference="slider_1">
    <material>Gazebo/Silver</material>
    <mu1>0.2</mu1>
    <mu2>0.2</mu2>
    <selfCollide>true</selfCollide>
  </gazebo>
  <gazebo reference="Impact_plate_1">
    <material>Gazebo/Silver</material>
    <mu1>0.2</mu1>
    <mu2>0.2</mu2>
    <selfCollide>true</selfCollide>
  </gazebo>
  <gazebo reference="shaft_1">
    <material>Gazebo/Silver</material>
    <mu1>0.2</mu1>
    <mu2>0.2</mu2>
    <selfCollide>true</selfCollide>
  </gazebo>
  <gazebo reference="Wall_1">
    <material>Gazebo/Silver</material>
    <mu1>0.2</mu1>
    <mu2>0.2</mu2>
    <selfCollide>true</selfCollide>
  </gazebo>
  <link name="base_link">
    <inertial>
      <origin rpy="0 0 0" xyz="-0.05999999999999999 0.2 0.005"/>
      <mass value="3.768"/>
      <inertia ixx="0.050271" ixy="0.0" ixz="0.0" iyy="0.004553" iyz="0.0" izz="0.054762"/>
    </inertial>
    <visual>
      <origin rpy="0 0 0" xyz="0 0 0"/>
      <geometry>
        <mesh filename="../meshes/base_link.stl" scale="0.001 0.001 0.001"/>
      </geometry>
      <material name="silver"/>
    </visual>
    <collision>
      <origin rpy="0 0 0" xyz="0 0 0"/>
      <geometry>
        <mesh filename="../meshes/base_link.stl" scale="0.001 0.001 0.001"/>
      </geometry>
    </collision>
  </link>
  <link name="braket1_1">
    <inertial>
      <origin rpy="0 0 0" xyz="0.0 0.0 0.004999999999999999"/>
      <mass value="0.28259999999999996"/>
      <inertia ixx="8.7e-05" ixy="0.0" ixz="0.0" iyy="8.7e-05" iyz="0.0" izz="0.00017"/>
    </inertial>
    <visual>
      <origin rpy="0 0 0" xyz="0.085 -0.085 -0.01"/>
      <geometry>
        <mesh filename="../meshes/braket1_1.stl" scale="0.001 0.001 0.001"/>
      </geometry>
      <material name="silver"/>
    </visual>
    <collision>
      <origin rpy="0 0 0" xyz="0.085 -0.085 -0.01"/>
      <geometry>
        <mesh filename="../meshes/braket1_1.stl" scale="0.001 0.001 0.001"/>
      </geometry>
    </collision>
  </link>
  <link name="braket2_1">
    <inertial>
      <origin rpy="0 0 0" xyz="-1.3877787807814457e-17 2.0637658249000879e-13 0.030000000000000002"/>
      <mass value="0.24406640260831106"/>
      <inertia ixx="0.000167" ixy="-0.0" ixz="-0.0" iyy="8.5e-05" iyz="0.0" izz="8.5e-05"/>
    </inertial>
    <visual>
      <origin rpy="0 0 0" xyz="0.06 -0.085 -0.02"/>
      <geometry>
        <mesh filename="../meshes/braket2_1.stl" scale="0.001 0.001 0.001"/>
      </geometry>
      <material name="silver"/>
    </visual>
    <collision>
      <origin rpy="0 0 0" xyz="0.06 -0.085 -0.02"/>
      <geometry>
        <mesh filename="../meshes/braket2_1.stl" scale="0.001 0.001 0.001"/>
      </geometry>
    </collision>
  </link>
  <link name="motor_1">
    <inertial>
      <origin rpy="0 0 0" xyz="-0.019712452586152146 7.771561172376096e-15 0.0"/>
      <mass value="0.5513081044550306"/>
      <inertia ixx="0.000156" ixy="-0.0" ixz="0.0" iyy="0.000154" iyz="-0.0" izz="0.000154"/>
    </inertial>
    <visual>
      <origin rpy="0 0 0" xyz="0.065 -0.085 -0.05"/>
      <geometry>
        <mesh filename="../meshes/motor_1.stl" scale="0.001 0.001 0.001"/>
      </geometry>
      <material name="silver"/>
    </visual>
    <collision>
      <origin rpy="0 0 0" xyz="0.065 -0.085 -0.05"/>
      <geometry>
        <mesh filename="../meshes/motor_1.stl" scale="0.001 0.001 0.001"/>
      </geometry>
    </collision>
  </link>
  <link name="motor_shaft_1">
    <inertial>
      <origin rpy="0 0 0" xyz="0.009750000000000064 2.612909888455306e-13 -7.632783294297951e-17"/>
      <mass value="0.0030056205965517504"/>
      <inertia ixx="0.0" ixy="0.0" ixz="0.0" iyy="0.0" iyz="-0.0" izz="0.0"/>
    </inertial>
    <visual>
      <origin rpy="0 0 0" xyz="0.0625 -0.085 -0.05"/>
      <geometry>
        <mesh filename="../meshes/motor_shaft_1.stl" scale="0.001 0.001 0.001"/>
      </geometry>
      <material name="silver"/>
    </visual>
    <collision>
      <origin rpy="0 0 0" xyz="0.0625 -0.085 -0.05"/>
      <geometry>
        <mesh filename="../meshes/motor_shaft_1.stl" scale="0.001 0.001 0.001"/>
      </geometry>
    </collision>
  </link>
  <link name="Link1_1">
    <inertial>
      <origin rpy="0 0 0" xyz="-0.0050000000000000044 0.009999999999977804 0.0"/>
      <mass value="0.03632431220866493"/>
      <inertia ixx="4e-06" ixy="0.0" ixz="0.0" iyy="1e-06" iyz="0.0" izz="4e-06"/>
    </inertial>
    <visual>
      <origin rpy="0 0 0" xyz="0.043 -0.085 -0.05"/>
      <geometry>
        <mesh filename="../meshes/Link1_1.stl" scale="0.001 0.001 0.001"/>
      </geometry>
      <material name="silver"/>
    </visual>
    <collision>
      <origin rpy="0 0 0" xyz="0.043 -0.085 -0.05"/>
      <geometry>
        <mesh filename="../meshes/Link1_1.stl" scale="0.001 0.001 0.001"/>
      </geometry>
    </collision>
  </link>
  <link name="Link2_1">
    <inertial>
      <origin rpy="0 0 0" xyz="0.0049999999999999975 0.046999999999995226 0.0"/>
      <mass value="0.1671053122086649"/>
      <inertia ixx="0.000166" ixy="0.0" ixz="0.0" iyy="7e-06" iyz="0.0" izz="0.000161"/>
    </inertial>
    <visual>
      <origin rpy="0 0 0" xyz="0.043 -0.105 -0.05"/>
      <geometry>
        <mesh filename="../meshes/Link2_1.stl" scale="0.001 0.001 0.001"/>
      </geometry>
      <material name="silver"/>
    </visual>
    <collision>
      <origin rpy="0 0 0" xyz="0.043 -0.105 -0.05"/>
      <geometry>
        <mesh filename="../meshes/Link2_1.stl" scale="0.001 0.001 0.001"/>
      </geometry>
    </collision>
  </link>
  <link name="Link3_1">
    <inertial>
      <origin rpy="0 0 0" xyz="-0.00499999999998451 0.011274179443502064 0.0"/>
      <mass value="0.04501812215644751"/>
      <inertia ixx="5e-06" ixy="-0.0" ixz="0.0" iyy="2e-06" iyz="-0.0" izz="4e-06"/>
    </inertial>
    <visual>
      <origin rpy="0 0 0" xyz="0.043 -0.199 -0.05"/>
      <geometry>
        <mesh filename="../meshes/Link3_1.stl" scale="0.001 0.001 0.001"/>
      </geometry>
      <material name="silver"/>
    </visual>
    <collision>
      <origin rpy="0 0 0" xyz="0.043 -0.199 -0.05"/>
      <geometry>
        <mesh filename="../meshes/Link3_1.stl" scale="0.001 0.001 0.001"/>
      </geometry>
    </collision>
  </link>
  <link name="slider_jig_1">
    <inertial>
      <origin rpy="0 0 0" xyz="0.0 5.551115123125783e-17 0.016500000000000008"/>
      <mass value="0.3564528"/>
      <inertia ixx="8.7e-05" ixy="-0.0" ixz="0.0" iyy="6.3e-05" iyz="0.0" izz="8.5e-05"/>
    </inertial>
    <visual>
      <origin rpy="0 0 0" xyz="0.0475 -0.258 -0.01"/>
      <geometry>
        <mesh filename="../meshes/slider_jig_1.stl" scale="0.001 0.001 0.001"/>
      </geometry>
      <material name="silver"/>
    </visual>
    <collision>
      <origin rpy="0 0 0" xyz="0.0475 -0.258 -0.01"/>
      <geometry>
        <mesh filename="../meshes/slider_jig_1.stl" scale="0.001 0.001 0.001"/>
      </geometry>
    </collision>
  </link>
  <link name="slider_1">
    <inertial>
      <origin rpy="0 0 0" xyz="5.460909502374989e-14 5.551115123125783e-17 0.009232017697050052"/>
      <mass value="0.18510659684556105"/>
      <inertia ixx="3.4e-05" ixy="0.0" ixz="0.0" iyy="2.5e-05" iyz="0.0" izz="4.8e-05"/>
    </inertial>
    <visual>
      <origin rpy="0 0 0" xyz="0.0475 -0.258 -0.043"/>
      <geometry>
        <mesh filename="../meshes/slider_1.stl" scale="0.001 0.001 0.001"/>
      </geometry>
      <material name="silver"/>
    </visual>
    <collision>
      <origin rpy="0 0 0" xyz="0.0475 -0.258 -0.043"/>
      <geometry>
        <mesh filename="../meshes/slider_1.stl" scale="0.001 0.001 0.001"/>
      </geometry>
    </collision>
  </link>
  <link name="Impact_plate_1">
    <inertial>
      <origin rpy="0 0 0" xyz="-9.020562075079397e-17 0.0050000000000000044 0.0"/>
      <mass value="0.19624999999999998"/>
      <inertia ixx="4.3e-05" ixy="-0.0" ixz="-0.0" iyy="8.2e-05" iyz="-0.0" izz="4.3e-05"/>
    </inertial>
    <visual>
      <origin rpy="0 0 0" xyz="0.0475 -0.326 -0.05"/>
      <geometry>
        <mesh filename="../meshes/Impact_plate_1.stl" scale="0.001 0.001 0.001"/>
      </geometry>
      <material name="silver"/>
    </visual>
    <collision>
      <origin rpy="0 0 0" xyz="0.0475 -0.326 -0.05"/>
      <geometry>
        <mesh filename="../meshes/Impact_plate_1.stl" scale="0.001 0.001 0.001"/>
      </geometry>
    </collision>
  </link>
  <link name="shaft_1">
    <inertial>
      <origin rpy="0 0 0" xyz="3.0322966360074588e-15 0.034324110671936525 -2.7755575615628914e-17"/>
      <mass value="0.03899600056038747"/>
      <inertia ixx="3.4e-05" ixy="-0.0" ixz="-0.0" iyy="0.0" iyz="-0.0" izz="3.4e-05"/>
    </inertial>
    <visual>
      <origin rpy="0 0 0" xyz="0.0475 -0.2365 -0.05"/>
      <geometry>
        <mesh filename="../meshes/shaft_1.stl" scale="0.001 0.001 0.001"/>
      </geometry>
      <material name="silver"/>
    </visual>
    <collision>
      <origin rpy="0 0 0" xyz="0.0475 -0.2365 -0.05"/>
      <geometry>
        <mesh filename="../meshes/shaft_1.stl" scale="0.001 0.001 0.001"/>
      </geometry>
    </collision>
  </link>
  <link name="Wall_1">
    <inertial>
      <origin rpy="0 0 0" xyz="0.0 -0.01346153846153847 0.02653846153846154"/>
      <mass value="1.2246"/>
      <inertia ixx="0.001126" ixy="0.0" ixz="0.0" iyy="0.00223" iyz="0.000304" izz="0.001835"/>
    </inertial>
    <visual>
      <origin rpy="0 0 0" xyz="0.06 -0.37 -0.01"/>
      <geometry>
        <mesh filename="../meshes/Wall_1.stl" scale="0.001 0.001 0.001"/>
      </geometry>
      <material name="silver"/>
    </visual>
    <collision>
      <origin rpy="0 0 0" xyz="0.06 -0.37 -0.01"/>
      <geometry>
        <mesh filename="../meshes/Wall_1.stl" scale="0.001 0.001 0.001"/>
      </geometry>
    </collision>
  </link>
  <joint name="Rigid 7" type="fixed">
    <origin rpy="0 0 0" xyz="-0.085 0.085 0.01"/>
    <parent link="base_link"/>
    <child link="braket1_1"/>
  </joint>
  <joint name="Rigid 8" type="fixed">
    <origin rpy="0 0 0" xyz="0.025 0.0 0.01"/>
    <parent link="braket1_1"/>
    <child link="braket2_1"/>
  </joint>
  <joint name="Rigid 9" type="fixed">
    <origin rpy="0 0 0" xyz="-0.005 0.0 0.03"/>
    <parent link="braket2_1"/>
    <child link="motor_1"/>
  </joint>
  <joint name="Revolute 10" type="continuous">
    <origin rpy="0 0 0" xyz="0.0025 0.0 0.0"/>
    <parent link="motor_1"/>
    <child link="motor_shaft_1"/>
    <axis xyz="1.0 0.0 0.0"/>
  </joint>
  <joint name="Rigid 11" type="fixed">
    <origin rpy="0 0 0" xyz="0.0195 0.0 0.0"/>
    <parent link="motor_shaft_1"/>
    <child link="Link1_1"/>
  </joint>
  <joint name="Revolute 12" type="continuous">
    <origin rpy="0 0 0" xyz="0.0 0.02 0.0"/>
    <parent link="Link1_1"/>
    <child link="Link2_1"/>
    <axis xyz="-1.0 0.0 0.0"/>
  </joint>
  <joint name="Revolute 13" type="continuous">
    <origin rpy="0 0 0" xyz="0.0 0.094 0.0"/>
    <parent link="Link2_1"/>
    <child link="Link3_1"/>
    <axis xyz="-1.0 0.0 0.0"/>
  </joint>
  <joint name="Rigid 15" type="fixed">
    <origin rpy="0 0 0" xyz="-0.0475 0.258 0.01"/>
    <parent link="base_link"/>
    <child link="slider_jig_1"/>
  </joint>
  <joint name="Rigid 16" type="fixed">
    <origin rpy="0 0 0" xyz="0.0 0.0 0.033"/>
    <parent link="slider_jig_1"/>
    <child link="slider_1"/>
  </joint>
  <joint name="Rigid 17" type="fixed">
    <origin rpy="0 0 0" xyz="0.0 0.0895 0.0"/>
    <parent link="shaft_1"/>
    <child link="Impact_plate_1"/>
  </joint>
  <joint name="Slider 21" type="prismatic">
    <origin rpy="0 0 0" xyz="0.0 -0.0215 0.007"/>
    <parent link="slider_1"/>
    <child link="shaft_1"/>
    <axis xyz="0.0 -1.0 0.0"/>
    <limit effort="100" lower="0.0" upper="0.0" velocity="100"/>
  </joint>
  <joint name="Rigid 22" type="fixed">
    <origin rpy="0 0 0" xyz="-0.06 0.37 0.01"/>
    <parent link="base_link"/>
    <child link="Wall_1"/>
  </joint>
</robot>
